<?xml version="1.0" ?>
<!-- This URDF was automatically created by SolidWorks to URDF Exporter! Originally created by Stephen Brawner (brawner@gmail.com) 
     Commit Version: 1.6.0-4-g7f85cfe  Build Version: 1.6.7995.38578
     For more information, please see http://wiki.ros.org/sw_urdf_exporter -->
<robot
  name="car" xmlns:xacro="http://ros.org/wiki/xacro">
  <link name="dummy_link"></link>
  <link
    name="base_link">
    <inertial>
      <origin
        xyz="0.00470755801791906 1.11022302462516E-16 -0.0257454468120238"
        rpy="0 0 0" />
      <mass
        value="24.9831666875052" />
      <inertia
        ixx="0.535393521016459"
        ixy="3.47487696280531E-16"
        ixz="0.000725414459402336"
        iyy="1.91239117817699"
        iyz="-6.00231416576723E-19"
        izz="2.43625673542382" />
    </inertial>
    <visual>
      <origin
        xyz="0 0 0"
        rpy="0 0 0" />
      <geometry>
        <mesh
          filename="package://car/meshes/base_link.STL" />
      </geometry>
      <material
        name="">
        <color
          rgba="0.792156862745098 0.819607843137255 0.933333333333333 1" />
      </material>
    </visual>
    <collision>
      <origin
        xyz="0 0 0"
        rpy="0 0 0" />
      <geometry>
        <mesh
          filename="package://car/meshes/base_link.STL" />
      </geometry>
    </collision>
  </link>

  <joint name="dummy_joint" type="fixed">
    <origin rpy="0 0 0" xyz="0 0 0" />
    <parent link="dummy_link"/>
    <child link="base_link"/>
  </joint>

  <link
    name="left_hinge_front">
    <inertial>
      <origin
        xyz="-0.000120277605189206 -0.00350022524290428 0.0254000000000001"
        rpy="0 0 0" />
      <mass
        value="0.463471125188868" />
      <inertia
        ixx="0.00197270455567893"
        ixy="-6.11013623244948E-05"
        ixz="2.92397637481678E-20"
        iyy="0.000196679885199945"
        iyz="2.64224916325876E-19"
        izz="0.00197930187165054" />
    </inertial>
    <visual>
      <origin
        xyz="0 0 0"
        rpy="0 0 0" />
      <geometry>
        <mesh
          filename="package://car/meshes/left_hinge_front.STL" />
      </geometry>
      <material
        name="">
        <color
          rgba="0.792156862745098 0.819607843137255 0.933333333333333 1" />
      </material>
    </visual>
    <collision>
      <origin
        xyz="0 0 0"
        rpy="0 0 0" />
      <geometry>
        <mesh
          filename="package://car/meshes/left_hinge_front.STL" />
      </geometry>
    </collision>
  </link>
  <joint
    name="lefthingefront"
    type="revolute">
    <origin
      xyz="0.26023 0.2032 -0.1016"
      rpy="0 0 0.038642" />
    <parent
      link="base_link" />
    <child
      link="left_hinge_front" />
    <axis
      xyz="0 0 -1" />
    <limit
      lower="-3.14"
      upper="3.14"
      effort="0"
      velocity="0" />
  </joint>
  <link
    name="Left_wheel_front">
    <inertial>
      <origin
        xyz="-0.00306681650698584 -2.22044604925031E-16 0.0476632992826546"
        rpy="0 0 0" />
      <mass
        value="2.45721103449607" />
      <inertia
        ixx="0.00756591249272881"
        ixy="1.0283575538749E-18"
        ixz="-2.22681465401599E-05"
        iyy="0.00756581690842141"
        iyz="-1.88457462443331E-19"
        izz="0.0127535968260122" />
    </inertial>
    <visual>
      <origin
        xyz="0 0 0"
        rpy="0 0 0" />
      <geometry>
        <mesh
          filename="package://car/meshes/Left_wheel_front.STL" />
      </geometry>
      <material
        name="">
        <color
          rgba="0.792156862745098 0.819607843137255 0.933333333333333 1" />
      </material>
    </visual>
    <collision>
      <origin
        xyz="0 0 0"
        rpy="0 0 0" />
      <geometry>
        <mesh
          filename="package://car/meshes/Left_wheel_front.STL" />
      </geometry>
    </collision>
  </link>
  <joint
    name="leftwheelfront"
    type="continuous">
    <origin
      xyz="0.0051485 0.066486 0.0254"
      rpy="-1.5708 0 -0.038642" />
    <parent
      link="left_hinge_front" />
    <child
      link="Left_wheel_front" />
    <axis
      xyz="-0.0042924 0 0.99999" />
  </joint>
  <link
    name="right_hinge_front">
    <inertial>
      <origin
        xyz="-7.59833866305626E-05 0.00350146683239372 0.0254"
        rpy="0 0 0" />
      <mass
        value="0.463471125188869" />
      <inertia
        ixx="0.00197396624132431"
        ixy="3.86134664937877E-05"
        ixz="-1.49124554135027E-20"
        iyy="0.00019541819955457"
        iyz="-2.49142633738966E-19"
        izz="0.00197930187165054" />
    </inertial>
    <visual>
      <origin
        xyz="0 0 0"
        rpy="0 0 0" />
      <geometry>
        <mesh
          filename="package://car/meshes/right_hinge_front.STL" />
      </geometry>
      <material
        name="">
        <color
          rgba="0.792156862745098 0.819607843137255 0.933333333333333 1" />
      </material>
    </visual>
    <collision>
      <origin
        xyz="0 0 0"
        rpy="0 0 0" />
      <geometry>
        <mesh
          filename="package://car/meshes/right_hinge_front.STL" />
      </geometry>
    </collision>
  </link>
  <joint
    name="righthingefront"
    type="revolute">
    <origin
      xyz="0.26023 -0.2032 -0.1016"
      rpy="0 0 0" />
    <parent
      link="base_link" />
    <child
      link="right_hinge_front" />
    <axis
      xyz="0 0 -1" />
    <limit
      lower="-3.14"
      upper="3.14"
      effort="0"
      velocity="0" />
  </joint>
  <link
    name="right_wheel_front">
    <inertial>
      <origin
        xyz="-0.00055358895971408 0 -0.0380130301891577"
        rpy="0 0 0" />
      <mass
        value="2.45721103449608" />
      <inertia
        ixx="0.00756825877729745"
        ixy="6.67749374612028E-19"
        ixz="-0.000112526214711238"
        iyy="0.00756581690842142"
        iyz="1.564637453037E-18"
        izz="0.0127512505414436" />
    </inertial>
    <visual>
      <origin
        xyz="0 0 0"
        rpy="0 0 0" />
      <geometry>
        <mesh
          filename="package://car/meshes/right_wheel_front.STL" />
      </geometry>
      <material
        name="">
        <color
          rgba="0.792156862745098 0.819607843137255 0.933333333333333 1" />
      </material>
    </visual>
    <collision>
      <origin
        xyz="0 0 0"
        rpy="0 0 0" />
      <geometry>
        <mesh
          filename="package://car/meshes/right_wheel_front.STL" />
      </geometry>
    </collision>
  </link>
  <joint
    name="rightwheelfront"
    type="continuous">
    <origin
      xyz="0.0030334 -0.07626 0.0254"
      rpy="-1.5708 0 0" />
    <parent
      link="right_hinge_front" />
    <child
      link="right_wheel_front" />
    <axis
      xyz="0.021695 0 -0.99976" />
  </joint>
  <link
    name="left_hinge_back">
    <inertial>
      <origin
        xyz="-0.00608319327731166 0.0980977088280104 0.0132336134453781"
        rpy="0 0 0" />
      <mass
        value="0.463471125188868" />
      <inertia
        ixx="0.00197480417071053"
        ixy="1.17512027222171E-17"
        ixz="1.73229024851307E-22"
        iyy="0.000194580270168345"
        iyz="2.14137992207302E-19"
        izz="0.00197930187165054" />
    </inertial>
    <visual>
      <origin
        xyz="0 0 0"
        rpy="0 0 0" />
      <geometry>
        <mesh
          filename="package://car/meshes/left_hinge_back.STL" />
      </geometry>
      <material
        name="">
        <color
          rgba="0.792156862745098 0.819607843137255 0.933333333333333 1" />
      </material>
    </visual>
    <collision>
      <origin
        xyz="0 0 0"
        rpy="0 0 0" />
      <geometry>
        <mesh
          filename="package://car/meshes/left_hinge_back.STL" />
      </geometry>
    </collision>
  </link>
  <joint
    name="lefthingeback"
    type="fixed">
    <origin
      xyz="-0.24169 0.1016 -0.089434"
      rpy="0 0 0" />
    <parent
      link="base_link" />
    <child
      link="left_hinge_back" />
    <axis
      xyz="0 0 0" />
  </joint>
  <link
    name="left_wheel_back">
    <inertial>
      <origin
        xyz="5.55111512312578E-16 -2.22044604925031E-16 0.0381"
        rpy="0 0 0" />
      <mass
        value="2.45721103449607" />
      <inertia
        ixx="0.00756581690842141"
        ixy="-4.26086374897843E-19"
        ixz="-3.48296029793558E-17"
        iyy="0.00756581690842142"
        iyz="-2.88541231556167E-20"
        izz="0.0127536924103196" />
    </inertial>
    <visual>
      <origin
        xyz="0 0 0"
        rpy="0 0 0" />
      <geometry>
        <mesh
          filename="package://car/meshes/left_wheel_back.STL" />
      </geometry>
      <material
        name="">
        <color
          rgba="0.792156862745098 0.819607843137255 0.933333333333333 1" />
      </material>
    </visual>
    <collision>
      <origin
        xyz="0 0 0"
        rpy="0 0 0" />
      <geometry>
        <mesh
          filename="package://car/meshes/left_wheel_back.STL" />
      </geometry>
    </collision>
  </link>
  <joint
    name="leftwheelback"
    type="continuous">
    <origin
      xyz="-0.0060832 0.1778 0.013234"
      rpy="-1.5708 0 0" />
    <parent
      link="left_hinge_back" />
    <child
      link="left_wheel_back" />
    <axis
      xyz="0 0 1" />
  </joint>
  <link
    name="right_hinge_back">
    <inertial>
      <origin
        xyz="0.00608319327731088 -0.0980977088280104 0.0132336134453781"
        rpy="0 0 0" />
      <mass
        value="0.463471125188868" />
      <inertia
        ixx="0.00197480417071053"
        ixy="-1.92674564203676E-19"
        ixz="-2.63421034547483E-22"
        iyy="0.000194580270168346"
        iyz="-2.72975061386773E-19"
        izz="0.00197930187165054" />
    </inertial>
    <visual>
      <origin
        xyz="0 0 0"
        rpy="0 0 0" />
      <geometry>
        <mesh
          filename="package://car/meshes/right_hinge_back.STL" />
      </geometry>
      <material
        name="">
        <color
          rgba="0.792156862745098 0.819607843137255 0.933333333333333 1" />
      </material>
    </visual>
    <collision>
      <origin
        xyz="0 0 0"
        rpy="0 0 0" />
      <geometry>
        <mesh
          filename="package://car/meshes/right_hinge_back.STL" />
      </geometry>
    </collision>
  </link>
  <joint
    name="righthingeback"
    type="fixed">
    <origin
      xyz="-0.25386 -0.1016 -0.089434"
      rpy="0 0 0" />
    <parent
      link="base_link" />
    <child
      link="right_hinge_back" />
    <axis
      xyz="0 0 0" />
  </joint>
  <link
    name="right_wheel_back">
    <inertial>
      <origin
        xyz="0 0 -0.0381"
        rpy="0 0 0" />
      <mass
        value="2.45721103449608" />
      <inertia
        ixx="0.00756581690842141"
        ixy="3.07243844122817E-34"
        ixz="9.93953842907557E-19"
        iyy="0.00756581690842141"
        iyz="-1.71100024437671E-35"
        izz="0.0127536924103196" />
    </inertial>
    <visual>
      <origin
        xyz="0 0 0"
        rpy="0 0 0" />
      <geometry>
        <mesh
          filename="package://car/meshes/right_wheel_back.STL" />
      </geometry>
      <material
        name="">
        <color
          rgba="0.792156862745098 0.819607843137255 0.933333333333333 1" />
      </material>
    </visual>
    <collision>
      <origin
        xyz="0 0 0"
        rpy="0 0 0" />
      <geometry>
        <mesh
          filename="package://car/meshes/right_wheel_back.STL" />
      </geometry>
    </collision>
  </link>
  <joint
    name="rightwheelback"
    type="continuous">
    <origin
      xyz="0.0060832 -0.1778 0.013234"
      rpy="-1.5708 0 0" />
    <parent
      link="right_hinge_back" />
    <child
      link="right_wheel_back" />
    <axis
      xyz="0 0 -1" />
  </joint>
  <link
    name="lidar_link">
    <inertial>
      <origin
        xyz="0 -0.01 0.0508"
        rpy="0 0 0" />
      <mass
        value="0.823703678020892" />
      <inertia
        ixx="0.00123998155146124"
        ixy="2.12072395209952E-51"
        ixz="6.93649765430231E-35"
        iyy="0.00123998155146124"
        iyz="-4.10781393993733E-36"
        izz="0.00106284132982392" />
    </inertial>
    <visual>
      <origin
        xyz="0 0 0"
        rpy="0 0 0" />
      <geometry>
        <mesh
          filename="package://car/meshes/lidar_link.STL" />
      </geometry>
      <material
        name="">
        <color
          rgba="0.792156862745098 0.819607843137255 0.933333333333333 1" />
      </material>
    </visual>
    <collision>
      <origin
        xyz="0 0 0"
        rpy="0 0 0" />
      <geometry>
        <mesh
          filename="package://car/meshes/lidar_link.STL" />
      </geometry>
    </collision>
  </link>
  <joint
    name="lidar_joint"
    type="fixed">
    <origin
      xyz="0.37453 -0.01 0"
      rpy="0 0 3.1416" />
    <parent
      link="base_link" />
    <child
      link="lidar_link" />
    <axis
      xyz="0 0 1" />
  </joint>

      <ros2_control name="GazeboSystem" type="system">
 <hardware>
     <plugin>gazebo_ros2_control/GazeboSystem</plugin>
 </hardware>
 <!-- # Velocity Controllers -->

 <joint name="leftwheelfront">
     <command_interface name="velocity">
         <param name="min">-1000.0</param>
         <param name="max">1000.0</param>
     </command_interface>
     <state_interface name="position"/>
     <state_interface name="velocity"/>
 </joint>

  <joint name="rightwheelfront">
     <command_interface name="velocity">
         <param name="min">-1000.0</param>
         <param name="max">1000.0</param>
     </command_interface>
     <state_interface name="position"/>
     <state_interface name="velocity"/>
 </joint>

  <joint name="leftwheelback">
     <command_interface name="velocity">
         <param name="min">-1000.0</param>
         <param name="max">1000.0</param>
     </command_interface>
     <state_interface name="position"/>
     <state_interface name="velocity"/>
 </joint>

  <joint name="rightwheelback">
     <command_interface name="velocity">
         <param name="min">-1000.0</param>
         <param name="max">1000.0</param>
     </command_interface>
     <state_interface name="position"/>
     <state_interface name="velocity"/>
 </joint>

<!-- # Position Controller -->
 <joint name="lefthingefront">
     <command_interface name="position">
         <param name="min">-3.14</param>
         <param name="max">3.14</param>
     </command_interface>
     <state_interface name="position"/>
     <state_interface name="velocity"/>
 </joint>

  <joint name="righthingefront">
     <command_interface name="position">
         <param name="min">-3.14</param>
         <param name="max">3.14</param>
     </command_interface>
     <state_interface name="position"/>
     <state_interface name="velocity"/>
 </joint>

 </ros2_control>

 <gazebo>
    <plugin filename="libgazebo_ros2_control.so" name="gazebo_ros2_control">
        <parameters>$(find car)/config/control.yaml</parameters>
    </plugin>
 </gazebo>

 <gazebo reference="lidar_link">
  <sensor name="lidar" type="ray">
    <pose>0.0 0.0 0.227 0 0 0</pose>
    <always_on>true</always_on>
    <visualize>true</visualize>
    <update_rate>5</update_rate>
    <ray>
      <scan>
        <horizontal>
          <samples>360</samples>
          <resolution>1.00000</resolution>
          <min_angle>0.000000</min_angle>
          <max_angle>6.280000</max_angle>
        </horizontal>
      </scan>
      <range>
        <min>0.120000</min>
        <max>3.5</max>
        <resolution>0.015000</resolution>
      </range>
      <noise>
        <type>gaussian</type>
        <mean>0.0</mean>
        <stddev>0.01</stddev>
      </noise>
    </ray>
    <plugin name="scan" filename="libgazebo_ros_ray_sensor.so">
      <ros>
        <remapping>~/out:=scan</remapping>
      </ros>
      <output_type>sensor_msgs/LaserScan</output_type>
      <frame_name>lidar_link</frame_name>
    </plugin>
  </sensor>
  </gazebo>

  <gazebo reference="base_link">
  <gravity>true</gravity>
  <sensor name="imu_sensor" type="imu">
    <always_on>true</always_on>
    <update_rate>100</update_rate>
    <visualize>true</visualize>
    <topic>__default_topic__</topic>
    <plugin filename="libgazebo_ros_imu_sensor.so" name="imu_plugin">
      <topicName>imu</topicName>
      <bodyName>base_link</bodyName>
      <updateRateHZ>10.0</updateRateHZ>
      <gaussianNoise>0.0</gaussianNoise>
      <xyzOffset>0 0 0</xyzOffset>
      <rpyOffset>0 0 0</rpyOffset>
      <frameName>base_link</frameName>
      <initialOrientationAsReference>false</initialOrientationAsReference>
    </plugin>
    <pose>0 0 0 0 0 0</pose>
  </sensor>
</gazebo>

</robot>